<?xml version="1.0"?>
<robot name="tiramisu">

  <!-- Root link -->
  <link name="world"/>

  <!-- Tiramisu link -->
  <link name="tiramisu"/>

  <!-- Tiramisu base link -->
  <link name="tiramisubaselink">
    <visual>
      <geometry>
        <mesh filename="package://rviz_transformations/meshes/tiramisu.stl" scale="0.00075 0.00075 0.00075"/>
      </geometry>
      <material name="blue">
        <color rgba="0 1 0 1"/>
      </material>
    </visual>
  </link>

  <joint name="world_to_tiramisu" type="floating">
    <parent link="world"/>
    <child link="tiramisu"/>
    <origin xyz="0 0 0" rpy="0 0 0"/>
  </joint>

  <joint name="tiramisu_to_tiramisubaselink" type="fixed">
    <parent link="tiramisu"/>
    <child link="tiramisubaselink"/>
    <origin xyz="0 0 0" rpy="0 0 0"/>
  </joint>

</robot>